Workbook

Sheet Raw_Gold
B1: USD
A2: 28521 | B2: 207.83
A3: 28549 | B3: 227.27
A4: 28580 | B4: 245.67
A5: 28608 | B5: 242.05
A6: 28641 | B6: 239.16
A7: 28671 | B7: 257.62
A8: 28702 | B8: 279.07
A9: 28733 | B9: 294.74
A10: 28762 | B10: 300.82
A11: 28794 | B11: 355.11
A12: 28824 | B12: 391.66
A13: 28853 | B13: 391.99
... A582: 46171 | B582: 4587.52

Sheet Raw_DXY
A1: observation_date | B1: DTWEXBGS
A2: 38719 | B2: 101.4155
A3: 38720 | B3: 100.7558
A4: 38721 | B4: 100.2288
A5: 38722 | B5: 100.2992
A6: 38723 | B6: 100.0241
A7: 38726 | B7: 100.1794
A8: 38727 | B8: 100.1436
A9: 38728 | B9: 99.871
A10: 38729 | B10: 100.0643
A11: 38730 | B11: 99.9675
A12: 38733 | B12: 99.9715
A13: 38734 | B13: 100.2447
... A262: 39083 | B262: 97.0323
A263: 39084
A264: 39085 | B264: 97.1281
A265: 39086 | B265: 97.5251
A266: 39087 | B266: 97.7801
A267: 39090 | B267: 97.788
A268: 39091 | B268: 97.9642
A269: 39092 | B269: 98.0943
A270: 39093 | B270: 98.0845
A271: 39094 | B271: 97.921
A272: 39097 | B272: 97.9201
A273: 39098 | B273: 97.9816
A274: 39099 | B274: 97.7509
A275: 39100 | B275: 97.8286
... A784: 39813 | B784: 98.6518
A785: 39814
A786: 39815 | B786: 98.6008
A787: 39818 | B787: 98.9195
A788: 39819 | B788: 98.7871
A789: 39820 | B789: 98.089
A790: 39821 | B790: 98.3223
A791: 39822 | B791: 98.8752
A792: 39825 | B792: 99.6022
A793: 39826 | B793: 100.3597
A794: 39827 | B794: 100.7546
A795: 39828 | B795: 101.4653
A796: 39829 | B796: 100.711
...

Sheet Raw_Real_Rate
A1: observation_date | B1: DFII10
A2: 38720 | B2: 2.03
A3: 38721 | B3: 2.01
A4: 38722 | B4: 2.04
A5: 38723 | B5: 2.05
A6: 38726 | B6: 2.05
A7: 38727 | B7: 2.06
A8: 38728 | B8: 2.07
A9: 38729 | B9: 2.01
A10: 38730 | B10: 1.97
A11: 38733
A12: 38734 | B12: 1.95
A13: 38735 | B13: 1.97
A14: 38736 | B14: 1.97
A15: 38737 | B15: 1.94
A16: 38740 | B16: 1.94
A17: 38741 | B17: 1.97
A18: 38742 | B18: 2.03
A19: 38743 | B19: 2.01
A20: 38744 | B20: 2.02
A21: 38747 | B21: 2.03
A22: 38748 | B22: 2
A23: 38749 | B23: 2.02
... A35: 38765 | B35: 2.03
A36: 38768
A37: 38769 | B37: 2.04
A38: 38770 | B38: 2.01
A39: 38771 | B39: 2.03
A40: 38772 | B40: 2.02
A41: 38775 | B41: 2.04
A42: 38776 | B42: 2.02
A43: 38777 | B43: 2.02
A44: 38778 | B44: 2.05
A45: 38779 | B45: 2.07
A46: 38782 | B46: 2.14
A47: 38783 | B47: 2.16
A48: 38784 | B48: 2.2
... A74: 38820 | B74: 2.48
A75: 38821
A76: 38824 | B76: 2.43
...

Sheet Raw_Oil
A1: Date | B1: Cushing, OK WTI Spot Price FOB (Dollars per Barrel)
A2: 31414 | B2: 25.56
A3: 31415 | B3: 26
A4: 31418 | B4: 26.53
A5: 31419 | B5: 25.85
A6: 31420 | B6: 25.87
A7: 31421 | B7: 26.03
A8: 31422 | B8: 25.65
A9: 31425 | B9: 25.08
A10: 31426 | B10: 24.97
A11: 31427 | B11: 25.18
A12: 31428 | B12: 23.98
A13: 31429 | B13: 23.63
... A350: 31919 | B350: 19.68
A351: 31922
A352: 31923 | B352: 19.35
A353: 31924 | B353: 19.38
A354: 31925 | B354: 19.28
A355: 31926 | B355: 19.36
A356: 31929 | B356: 19.55
A357: 31930 | B357: 19.7
A358: 31931 | B358: 19.87
A359: 31932 | B359: 19.75
A360: 31933 | B360: 19.79
A361: 31936 | B361: 19.94
A362: 31937 | B362: 19.84
A363: 31938 | B363: 19.83
... A483: 32106 | B483: 18.63
A484: 32107
A485: 32108 | B485: 18.63
A486: 32111 | B486: 18.52
A487: 32112 | B487: 18.44
A488: 32113 | B488: 18.59
A489: 32114 | B489: 18.87
A490: 32115 | B490: 18.68
A491: 32118 | B491: 18.3
A492: 32119 | B492: 18.06
A493: 32120 | B493: 18.53
A494: 32121 | B494: 18.51
A495: 32122 | B495: 18.31
...

Sheet Raw_Inflation
A1: observation_date | B1: T10YIE
A2: 37623 | B2: 1.64
A3: 37624 | B3: 1.62
A4: 37627 | B4: 1.63
A5: 37628 | B5: 1.62
A6: 37629 | B6: 1.71
A7: 37630 | B7: 1.78
A8: 37631 | B8: 1.75
A9: 37634 | B9: 1.77
A10: 37635 | B10: 1.76
A11: 37636 | B11: 1.8
A12: 37637 | B12: 1.79
A13: 37638 | B13: 1.8
A14: 37641
A15: 37642 | B15: 1.78
A16: 37643 | B16: 1.72
A17: 37644 | B17: 1.78
A18: 37645 | B18: 1.8
A19: 37648 | B19: 1.82
A20: 37649 | B20: 1.81
A21: 37650 | B21: 1.85
A22: 37651 | B22: 1.8
A23: 37652 | B23: 1.81
A24: 37655 | B24: 1.81
A25: 37656 | B25: 1.84
A26: 37657 | B26: 1.9
... A33: 37666 | B33: 1.92
A34: 37669
A35: 37670 | B35: 1.89
A36: 37671 | B36: 1.89
A37: 37672 | B37: 1.94
A38: 37673 | B38: 1.97
A39: 37676 | B39: 1.99
A40: 37677 | B40: 1.97
A41: 37678 | B41: 1.94
A42: 37679 | B42: 1.94
A43: 37680 | B43: 1.94
A44: 37683 | B44: 1.91
A45: 37684 | B45: 1.88
A46: 37685 | B46: 1.88
...

Sheet Raw_CB_demand
A1: Quarter | B1: CB_demand
A2: Q1'10 | B2: 59.710231
A3: Q2'10 | B3: 14.214257
A4: Q3'10 | B4: 24.03588
A5: Q4'10 | B5: -18.809865
A6: Q1'11 | B6: 142.46376
A7: Q2'11 | B7: 69.444805
A8: Q3'11 | B8: 148.80804
A9: Q4'11 | B9: 120.06989
A10: Q1'12 | B10: 122.47402
A11: Q2'12 | B11: 170.69
A12: Q3'12 | B12: 117.75586
A13: Q4'12 | B13: 158.26341
... A66: Q1'26 | B66: 243.66413

Sheet Master Data
A1: DATE | B1: GOLD_USD | C1: DXY | D1: REAL_RATE | E1: OIL_WTI | F1: INFLATION_EXP | G1: CB_DEMAND_T | H1: GOLD_MOM_PCT | I1: DXY_MOM_PCT | J1: Period | K1: GOLD_VOL_12M | L1: ROLL_CORR_GOLD_DXY | M1: ROLL_CORR_GOLD_RATE
A2: 40179 | B2: {=IFERROR(INDEX(Raw_Gold!$B:$B, MATCH(1, (YEAR(Raw_Gold!$A:$A)=YEAR(A2))*(MONTH(Raw_Gold!$A:$A)=MONTH(A2)), 0)), "")} -> 1117.96 | C2: {=IFERROR(AVERAGEIFS(Raw_DXY!$B:$B, Raw_DXY!$A:$A, ">="&A2, Raw_DXY!$A:$A, "<"&EDATE(A2,1)), "")} -> 92.4403 | D2: =IFERROR(AVERAGEIFS(Raw_Real_Rate!$B:$B, Raw_Real_Rate!$A:$A, ">="&A2, Raw_Real_Rate!$A:$A, "<"&EDATE(A2,1)), "") -> 1.3747368 | E2: =IFERROR(AVERAGEIFS(Raw_Oil!$B:$B, Raw_Oil!$A:$A, ">="&A2, Raw_Oil!$A:$A, "<"&EDATE(A2,1)), "") -> 78.325789 | F2: {=IFERROR(AVERAGEIFS(Raw_Inflation!$B:$B, Raw_Inflation!$A:$A, ">="&A2, Raw_Inflation!$A:$A, "<"&EDATE(A2,1)), "")} -> 2.3584211 | G2: {=IFERROR(VLOOKUP("Q"&INT((MONTH(A2)+2)/3)&"'"&TEXT(YEAR(A2)-2000,"00"), Raw_CB_demand!$A:$B, 2, 0), "")} -> 59.710231 | J2: =IF(A2<DATE(2020,3,1),"1_Pre-COVID",IF(A2<DATE(2022,1,1),"2_COVID-Recovery",IF(A2<DATE(2024,1,1),"3_Fed-Hike","4_Bull-Conflict"))) -> 1_Pre-COVID
A3: =EDATE(A2,1) -> 40210 | B3: {=IFERROR(INDEX(Raw_Gold!$B:$B, MATCH(1, (YEAR(Raw_Gold!$A:$A)=YEAR(A3))*(MONTH(Raw_Gold!$A:$A)=MONTH(A3)), 0)), "")} -> 1095.41 | C3: {=IFERROR(AVERAGEIFS(Raw_DXY!$B:$B, Raw_DXY!$A:$A, ">="&A3, Raw_DXY!$A:$A, "<"&EDATE(A3,1)), "")} -> 93.88668 | D3: =IFERROR(AVERAGEIFS(Raw_Real_Rate!$B:$B, Raw_Real_Rate!$A:$A, ">="&A3, Raw_Real_Rate!$A:$A, "<"&EDATE(A3,1)), "") -> 1.4189474 | E3: =IFERROR(AVERAGEIFS(Raw_Oil!$B:$B, Raw_Oil!$A:$A, ">="&A3, Raw_Oil!$A:$A, "<"&EDATE(A3,1)), "") -> 76.387368 | F3: {=IFERROR(AVERAGEIFS(Raw_Inflation!$B:$B, Raw_Inflation!$A:$A, ">="&A3, Raw_Inflation!$A:$A, "<"&EDATE(A3,1)), "")} -> 2.2721053 | G3: {=IFERROR(VLOOKUP("Q"&INT((MONTH(A3)+2)/3)&"'"&TEXT(YEAR(A3)-2000,"00"), Raw_CB_demand!$A:$B, 2, 0), "")} -> 59.710231 | H3: =IFERROR((B3-B2)/B2, "") -> -0.020170668 | I3: =IFERROR((C3-C2)/C2*100, "") -> 1.5646639 | J3: =IF(A3<DATE(2020,3,1),"1_Pre-COVID",IF(A3<DATE(2022,1,1),"2_COVID-Recovery",IF(A3<DATE(2024,1,1),"3_Fed-Hike","4_Bull-Conflict"))) -> 1_Pre-COVID
A4: =EDATE(A3,1) -> 40238 | B4: {=IFERROR(INDEX(Raw_Gold!$B:$B, MATCH(1, (YEAR(Raw_Gold!$A:$A)=YEAR(A4))*(MONTH(Raw_Gold!$A:$A)=MONTH(A4)), 0)), "")} -> 1113.34 | C4: {=IFERROR(AVERAGEIFS(Raw_DXY!$B:$B, Raw_DXY!$A:$A, ">="&A4, Raw_DXY!$A:$A, "<"&EDATE(A4,1)), "")} -> 93.149878 | D4: =IFERROR(AVERAGEIFS(Raw_Real_Rate!$B:$B, Raw_Real_Rate!$A:$A, ">="&A4, Raw_Real_Rate!$A:$A, "<"&EDATE(A4,1)), "") -> 1.5082609 | E4: =IFERROR(AVERAGEIFS(Raw_Oil!$B:$B, Raw_Oil!$A:$A, ">="&A4, Raw_Oil!$A:$A, "<"&EDATE(A4,1)), "") -> 81.203478 | F4: {=IFERROR(AVERAGEIFS(Raw_Inflation!$B:$B, Raw_Inflation!$A:$A, ">="&A4, Raw_Inflation!$A:$A, "<"&EDATE(A4,1)), "")} -> 2.2191304 | G4: {=IFERROR(VLOOKUP("Q"&INT((MONTH(A4)+2)/3)&"'"&TEXT(YEAR(A4)-2000,"00"), Raw_CB_demand!$A:$B, 2, 0), "")} -> 59.710231 | H4: =IFERROR((B4-B3)/B3, "") -> 0.0163683 | I4: =IFERROR((C4-C3)/C3*100, "") -> -0.78477771 | J4: =IF(A4<DATE(2020,3,1),"1_Pre-COVID",IF(A4<DATE(2022,1,1),"2_COVID-Recovery",IF(A4<DATE(2024,1,1),"3_Fed-Hike","4_Bull-Conflict"))) -> 1_Pre-COVID
A5: =EDATE(A4,1) -> 40269 | B5: {=IFERROR(INDEX(Raw_Gold!$B:$B, MATCH(1, (YEAR(Raw_Gold!$A:$A)=YEAR(A5))*(MONTH(Raw_Gold!$A:$A)=MONTH(A5)), 0)), "")} -> 1148.69 | C5: {=IFERROR(AVERAGEIFS(Raw_DXY!$B:$B, Raw_DXY!$A:$A, ">="&A5, Raw_DXY!$A:$A, "<"&EDATE(A5,1)), "")} -> 92.639086 | D5: =IFERROR(AVERAGEIFS(Raw_Real_Rate!$B:$B, Raw_Real_Rate!$A:$A, ">="&A5, Raw_Real_Rate!$A:$A, "<"&EDATE(A5,1)), "") -> 1.5009091 | E5: =IFERROR(AVERAGEIFS(Raw_Oil!$B:$B, Raw_Oil!$A:$A, ">="&A5, Raw_Oil!$A:$A, "<"&EDATE(A5,1)), "") -> 84.292857 | F5: {=IFERROR(AVERAGEIFS(Raw_Inflation!$B:$B, Raw_Inflation!$A:$A, ">="&A5, Raw_Inflation!$A:$A, "<"&EDATE(A5,1)), "")} -> 2.3459091 | G5: {=IFERROR(VLOOKUP("Q"&INT((MONTH(A5)+2)/3)&"'"&TEXT(YEAR(A5)-2000,"00"), Raw_CB_demand!$A:$B, 2, 0), "")} -> 14.214257 | H5: =IFERROR((B5-B4)/B4, "") -> 0.031751307 | I5: =IFERROR((C5-C4)/C4*100, "") -> -0.54835487 | J5: =IF(A5<DATE(2020,3,1),"1_Pre-COVID",IF(A5<DATE(2022,1,1),"2_COVID-Recovery",IF(A5<DATE(2024,1,1),"3_Fed-Hike","4_Bull-Conflict"))) -> 1_Pre-COVID
A6: =EDATE(A5,1) -> 40299 | B6: {=IFERROR(INDEX(Raw_Gold!$B:$B, MATCH(1, (YEAR(Raw_Gold!$A:$A)=YEAR(A6))*(MONTH(Raw_Gold!$A:$A)=MONTH(A6)), 0)), "")} -> 1205.43 | C6: {=IFERROR(AVERAGEIFS(Raw_DXY!$B:$B, Raw_DXY!$A:$A, ">="&A6, Raw_DXY!$A:$A, "<"&EDATE(A6,1)), "")} -> 95.53064 | D6: =IFERROR(AVERAGEIFS(Raw_Real_Rate!$B:$B, Raw_Real_Rate!$A:$A, ">="&A6, Raw_Real_Rate!$A:$A, "<"&EDATE(A6,1)), "") -> 1.307 | E6: =IFERROR(AVERAGEIFS(Raw_Oil!$B:$B, Raw_Oil!$A:$A, ">="&A6, Raw_Oil!$A:$A, "<"&EDATE(A6,1)), "") -> 73.7435 | F6: {=IFERROR(AVERAGEIFS(Raw_Inflation!$B:$B, Raw_Inflation!$A:$A, ">="&A6, Raw_Inflation!$A:$A, "<"&EDATE(A6,1)), "")} -> 2.113 | G6: {=IFERROR(VLOOKUP("Q"&INT((MONTH(A6)+2)/3)&"'"&TEXT(YEAR(A6)-2000,"00"), Raw_CB_demand!$A:$B, 2, 0), "")} -> 14.214257 | H6: =IFERROR((B6-B5)/B5, "") -> 0.049395398 | I6: =IFERROR((C6-C5)/C5*100, "") -> 3.1213106 | J6: =IF(A6<DATE(2020,3,1),"1_Pre-COVID",IF(A6<DATE(2022,1,1),"2_COVID-Recovery",IF(A6<DATE(2024,1,1),"3_Fed-Hike","4_Bull-Conflict"))) -> 1_Pre-COVID
A7: =EDATE(A6,1) -> 40330 | B7: {=IFERROR(INDEX(Raw_Gold!$B:$B, MATCH(1, (YEAR(Raw_Gold!$A:$A)=YEAR(A7))*(MONTH(Raw_Gold!$A:$A)=MONTH(A7)), 0)), "")} -> 1232.92 | C7: {=IFERROR(AVERAGEIFS(Raw_DXY!$B:$B, Raw_DXY!$A:$A, ">="&A7, Raw_DXY!$A:$A, "<"&EDATE(A7,1)), "")} -> 96.060627 | D7: =IFERROR(AVERAGEIFS(Raw_Real_Rate!$B:$B, Raw_Real_Rate!$A:$A, ">="&A7, Raw_Real_Rate!$A:$A, "<"&EDATE(A7,1)), "") -> 1.2568182 | E7: =IFERROR(AVERAGEIFS(Raw_Oil!$B:$B, Raw_Oil!$A:$A, ">="&A7, Raw_Oil!$A:$A, "<"&EDATE(A7,1)), "") -> 75.335909 | F7: {=IFERROR(AVERAGEIFS(Raw_Inflation!$B:$B, Raw_Inflation!$A:$A, ">="&A7, Raw_Inflation!$A:$A, "<"&EDATE(A7,1)), "")} -> 1.9472727 | G7: {=IFERROR(VLOOKUP("Q"&INT((MONTH(A7)+2)/3)&"'"&TEXT(YEAR(A7)-2000,"00"), Raw_CB_demand!$A:$B, 2, 0), "")} -> 14.214257 | H7: =IFERROR((B7-B6)/B6, "") -> 0.02280514 | I7: =IFERROR((C7-C6)/C6*100, "") -> 0.5547825 | J7: =IF(A7<DATE(2020,3,1),"1_Pre-COVID",IF(A7<DATE(2022,1,1),"2_COVID-Recovery",IF(A7<DATE(2024,1,1),"3_Fed-Hike","4_Bull-Conflict"))) -> 1_Pre-COVID
A8: =EDATE(A7,1) -> 40360 | B8: {=IFERROR(INDEX(Raw_Gold!$B:$B, MATCH(1, (YEAR(Raw_Gold!$A:$A)=YEAR(A8))*(MONTH(Raw_Gold!$A:$A)=MONTH(A8)), 0)), "")} -> 1192.97 | C8: {=IFERROR(AVERAGEIFS(Raw_DXY!$B:$B, Raw_DXY!$A:$A, ">="&A8, Raw_DXY!$A:$A, "<"&EDATE(A8,1)), "")} -> 94.45469 | D8: =IFERROR(AVERAGEIFS(Raw_Real_Rate!$B:$B, Raw_Real_Rate!$A:$A, ">="&A8, Raw_Real_Rate!$A:$A, "<"&EDATE(A8,1)), "") -> 1.2409524 | E8: =IFERROR(AVERAGEIFS(Raw_Oil!$B:$B, Raw_Oil!$A:$A, ">="&A8, Raw_Oil!$A:$A, "<"&EDATE(A8,1)), "") -> 76.319524 | F8: {=IFERROR(AVERAGEIFS(Raw_Inflation!$B:$B, Raw_Inflation!$A:$A, ">="&A8, Raw_Inflation!$A:$A, "<"&EDATE(A8,1)), "")} -> 1.7704762 | G8: {=IFERROR(VLOOKUP("Q"&INT((MONTH(A8)+2)/3)&"'"&TEXT(YEAR(A8)-2000,"00"), Raw_CB_demand!$A:$B, 2, 0), "")} -> 24.03588 | H8: =IFERROR((B8-B7)/B7, "") -> -0.032402751 | I8: =IFERROR((C8-C7)/C7*100, "") -> -1.671795 | J8: =IF(A8<DATE(2020,3,1),"1_Pre-COVID",IF(A8<DATE(2022,1,1),"2_COVID-Recovery",IF(A8<DATE(2024,1,1),"3_Fed-Hike","4_Bull-Conflict"))) -> 1_Pre-COVID
A9: =EDATE(A8,1) -> 40391 | B9: {=IFERROR(INDEX(Raw_Gold!$B:$B, MATCH(1, (YEAR(Raw_Gold!$A:$A)=YEAR(A9))*(MONTH(Raw_Gold!$A:$A)=MONTH(A9)), 0)), "")} -> 1215.81 | C9: {=IFERROR(AVERAGEIFS(Raw_DXY!$B:$B, Raw_DXY!$A:$A, ">="&A9, Raw_DXY!$A:$A, "<"&EDATE(A9,1)), "")} -> 93.682232 | D9: =IFERROR(AVERAGEIFS(Raw_Real_Rate!$B:$B, Raw_Real_Rate!$A:$A, ">="&A9, Raw_Real_Rate!$A:$A, "<"&EDATE(A9,1)), "") -> 1.0218182 | E9: =IFERROR(AVERAGEIFS(Raw_Oil!$B:$B, Raw_Oil!$A:$A, ">="&A9, Raw_Oil!$A:$A, "<"&EDATE(A9,1)), "") -> 76.599091 | F9: {=IFERROR(AVERAGEIFS(Raw_Inflation!$B:$B, Raw_Inflation!$A:$A, ">="&A9, Raw_Inflation!$A:$A, "<"&EDATE(A9,1)), "")} -> 1.6768182 | G9: {=IFERROR(VLOOKUP("Q"&INT((MONTH(A9)+2)/3)&"'"&TEXT(YEAR(A9)-2000,"00"), Raw_CB_demand!$A:$B, 2, 0), "")} -> 24.03588 | H9: =IFERROR((B9-B8)/B8, "") -> 0.019145494 | I9: =IFERROR((C9-C8)/C8*100, "") -> -0.81780868 | J9: =IF(A9<DATE(2020,3,1),"1_Pre-COVID",IF(A9<DATE(2022,1,1),"2_COVID-Recovery",IF(A9<DATE(2024,1,1),"3_Fed-Hike","4_Bull-Conflict"))) -> 1_Pre-COVID
A10: =EDATE(A9,1) -> 40422 | B10: {=IFERROR(INDEX(Raw_Gold!$B:$B, MATCH(1, (YEAR(Raw_Gold!$A:$A)=YEAR(A10))*(MONTH(Raw_Gold!$A:$A)=MONTH(A10)), 0)), "")} -> 1270.98 | C10: {=IFERROR(AVERAGEIFS(Raw_DXY!$B:$B, Raw_DXY!$A:$A, ">="&A10, Raw_DXY!$A:$A, "<"&EDATE(A10,1)), "")} -> 92.762595 | D10: =IFERROR(AVERAGEIFS(Raw_Real_Rate!$B:$B, Raw_Real_Rate!$A:$A, ">="&A10, Raw_Real_Rate!$A:$A, "<"&EDATE(A10,1)), "") -> 0.90904762 | E10: =IFERROR(AVERAGEIFS(Raw_Oil!$B:$B, Raw_Oil!$A:$A, ">="&A10, Raw_Oil!$A:$A, "<"&EDATE(A10,1)), "") -> 75.241905 | F10: {=IFERROR(AVERAGEIFS(Raw_Inflation!$B:$B, Raw_Inflation!$A:$A, ">="&A10, Raw_Inflation!$A:$A, "<"&EDATE(A10,1)), "")} -> 1.7385714 | G10: {=IFERROR(VLOOKUP("Q"&INT((MONTH(A10)+2)/3)&"'"&TEXT(YEAR(A10)-2000,"00"), Raw_CB_demand!$A:$B, 2, 0), "")} -> 24.03588 | H10: =IFERROR((B10-B9)/B9, "") -> 0.045377156 | I10: =IFERROR((C10-C9)/C9*100, "") -> -0.98165529 | J10: =IF(A10<DATE(2020,3,1),"1_Pre-COVID",IF(A10<DATE(2022,1,1),"2_COVID-Recovery",IF(A10<DATE(2024,1,1),"3_Fed-Hike","4_Bull-Conflict"))) -> 1_Pre-COVID
A11: =EDATE(A10,1) -> 40452 | B11: {=IFERROR(INDEX(Raw_Gold!$B:$B, MATCH(1, (YEAR(Raw_Gold!$A:$A)=YEAR(A11))*(MONTH(Raw_Gold!$A:$A)=MONTH(A11)), 0)), "")} -> 1342.02 | C11: {=IFERROR(AVERAGEIFS(Raw_DXY!$B:$B, Raw_DXY!$A:$A, ">="&A11, Raw_DXY!$A:$A, "<"&EDATE(A11,1)), "")} -> 90.22912 | D11: =IFERROR(AVERAGEIFS(Raw_Real_Rate!$B:$B, Raw_Real_Rate!$A:$A, ">="&A11, Raw_Real_Rate!$A:$A, "<"&EDATE(A11,1)), "") -> 0.525 | E11: =IFERROR(AVERAGEIFS(Raw_Oil!$B:$B, Raw_Oil!$A:$A, ">="&A11, Raw_Oil!$A:$A, "<"&EDATE(A11,1)), "") -> 81.892857 | F11: {=IFERROR(AVERAGEIFS(Raw_Inflation!$B:$B, Raw_Inflation!$A:$A, ">="&A11, Raw_Inflation!$A:$A, "<"&EDATE(A11,1)), "")} -> 2.015 | G11: {=IFERROR(VLOOKUP("Q"&INT((MONTH(A11)+2)/3)&"'"&TEXT(YEAR(A11)-2000,"00"), Raw_CB_demand!$A:$B, 2, 0), "")} -> -18.809865 | H11: =IFERROR((B11-B10)/B10, "") -> 0.055893877 | I11: =IFERROR((C11-C10)/C10*100, "") -> -2.7311388 | J11: =IF(A11<DATE(2020,3,1),"1_Pre-COVID",IF(A11<DATE(2022,1,1),"2_COVID-Recovery",IF(A11<DATE(2024,1,1),"3_Fed-Hike","4_Bull-Conflict"))) -> 1_Pre-COVID
A12: =EDATE(A11,1) -> 40483 | B12: {=IFERROR(INDEX(Raw_Gold!$B:$B, MATCH(1, (YEAR(Raw_Gold!$A:$A)=YEAR(A12))*(MONTH(Raw_Gold!$A:$A)=MONTH(A12)), 0)), "")} -> 1369.89 | C12: {=IFERROR(AVERAGEIFS(Raw_DXY!$B:$B, Raw_DXY!$A:$A, ">="&A12, Raw_DXY!$A:$A, "<"&EDATE(A12,1)), "")} -> 90.509535 | D12: =IFERROR(AVERAGEIFS(Raw_Real_Rate!$B:$B, Raw_Real_Rate!$A:$A, ">="&A12, Raw_Real_Rate!$A:$A, "<"&EDATE(A12,1)), "") -> 0.666 | E12: =IFERROR(AVERAGEIFS(Raw_Oil!$B:$B, Raw_Oil!$A:$A, ">="&A12, Raw_Oil!$A:$A, "<"&EDATE(A12,1)), "") -> 84.252857 | F12: {=IFERROR(AVERAGEIFS(Raw_Inflation!$B:$B, Raw_Inflation!$A:$A, ">="&A12, Raw_Inflation!$A:$A, "<"&EDATE(A12,1)), "")} -> 2.097 | G12: {=IFERROR(VLOOKUP("Q"&INT((MONTH(A12)+2)/3)&"'"&TEXT(YEAR(A12)-2000,"00"), Raw_CB_demand!$A:$B, 2, 0), "")} -> -18.809865 | H12: =IFERROR((B12-B11)/B11, "") -> 0.020767202 | I12: =IFERROR((C12-C11)/C11*100, "") -> 0.31078104 | J12: =IF(A12<DATE(2020,3,1),"1_Pre-COVID",IF(A12<DATE(2022,1,1),"2_COVID-Recovery",IF(A12<DATE(2024,1,1),"3_Fed-Hike","4_Bull-Conflict"))) -> 1_Pre-COVID
A13: =EDATE(A12,1) -> 40513 | B13: {=IFERROR(INDEX(Raw_Gold!$B:$B, MATCH(1, (YEAR(Raw_Gold!$A:$A)=YEAR(A13))*(MONTH(Raw_Gold!$A:$A)=MONTH(A13)), 0)), "")} -> 1390.55 | C13: {=IFERROR(AVERAGEIFS(Raw_DXY!$B:$B, Raw_DXY!$A:$A, ">="&A13, Raw_DXY!$A:$A, "<"&EDATE(A13,1)), "")} -> 91.183471 | D13: =IFERROR(AVERAGEIFS(Raw_Real_Rate!$B:$B, Raw_Real_Rate!$A:$A, ">="&A13, Raw_Real_Rate!$A:$A, "<"&EDATE(A13,1)), "") -> 1.0440909 | E13: =IFERROR(AVERAGEIFS(Raw_Oil!$B:$B, Raw_Oil!$A:$A, ">="&A13, Raw_Oil!$A:$A, "<"&EDATE(A13,1)), "") -> 89.145909 | F13: {=IFERROR(AVERAGEIFS(Raw_Inflation!$B:$B, Raw_Inflation!$A:$A, ">="&A13, Raw_Inflation!$A:$A, "<"&EDATE(A13,1)), "")} -> 2.2468182 | G13: {=IFERROR(VLOOKUP("Q"&INT((MONTH(A13)+2)/3)&"'"&TEXT(YEAR(A13)-2000,"00"), Raw_CB_demand!$A:$B, 2, 0), "")} -> -18.809865 | H13: =IFERROR((B13-B12)/B12, "") -> 0.015081503 | I13: =IFERROR((C13-C12)/C12*100, "") -> 0.74460269 | J13: =IF(A13<DATE(2020,3,1),"1_Pre-COVID",IF(A13<DATE(2022,1,1),"2_COVID-Recovery",IF(A13<DATE(2024,1,1),"3_Fed-Hike","4_Bull-Conflict"))) -> 1_Pre-COVID
A14: =EDATE(A13,1) -> 40544 | B14: {=IFERROR(INDEX(Raw_Gold!$B:$B, MATCH(1, (YEAR(Raw_Gold!$A:$A)=YEAR(A14))*(MONTH(Raw_Gold!$A:$A)=MONTH(A14)), 0)), "")} -> 1356.4 | C14: {=IFERROR(AVERAGEIFS(Raw_DXY!$B:$B, Raw_DXY!$A:$A, ">="&A14, Raw_DXY!$A:$A, "<"&EDATE(A14,1)), "")} -> 90.11122 | D14: =IFERROR(AVERAGEIFS(Raw_Real_Rate!$B:$B, Raw_Real_Rate!$A:$A, ">="&A14, Raw_Real_Rate!$A:$A, "<"&EDATE(A14,1)), "") -> 1.0605 | E14: =IFERROR(AVERAGEIFS(Raw_Oil!$B:$B, Raw_Oil!$A:$A, ">="&A14, Raw_Oil!$A:$A, "<"&EDATE(A14,1)), "") -> 89.1705 | F14: {=IFERROR(AVERAGEIFS(Raw_Inflation!$B:$B, Raw_Inflation!$A:$A, ">="&A14, Raw_Inflation!$A:$A, "<"&EDATE(A14,1)), "")} -> 2.3335 | G14: {=IFERROR(VLOOKUP("Q"&INT((MONTH(A14)+2)/3)&"'"&TEXT(YEAR(A14)-2000,"00"), Raw_CB_demand!$A:$B, 2, 0), "")} -> 142.46376 | H14: =IFERROR((B14-B13)/B13, "") -> -0.024558628 | I14: =IFERROR((C14-C13)/C13*100, "") -> -1.1759274 | J14: =IF(A14<DATE(2020,3,1),"1_Pre-COVID",IF(A14<DATE(2022,1,1),"2_COVID-Recovery",IF(A14<DATE(2024,1,1),"3_Fed-Hike","4_Bull-Conflict"))) -> 1_Pre-COVID | K14: =IFERROR(_xlfn.STDEV.S(H3:H14), "") -> 0.028903163 | L14: =IFERROR(CORREL(B3:B14,C3:C14),"") -> -0.67696211 | M14: =IFERROR(CORREL(B3:B14,D3:D14),"") -> -0.80807038
A15: =EDATE(A14,1) -> 40575 | B15: {=IFERROR(INDEX(Raw_Gold!$B:$B, MATCH(1, (YEAR(Raw_Gold!$A:$A)=YEAR(A15))*(MONTH(Raw_Gold!$A:$A)=MONTH(A15)), 0)), "")} -> 1372.73 | C15: {=IFERROR(AVERAGEIFS(Raw_DXY!$B:$B, Raw_DXY!$A:$A, ">="&A15, Raw_DXY!$A:$A, "<"&EDATE(A15,1)), "")} -> 89.396689 | D15: =IFERROR(AVERAGEIFS(Raw_Real_Rate!$B:$B, Raw_Real_Rate!$A:$A, ">="&A15, Raw_Real_Rate!$A:$A, "<"&EDATE(A15,1)), "") -> 1.2378947 | E15: =IFERROR(AVERAGEIFS(Raw_Oil!$B:$B, Raw_Oil!$A:$A, ">="&A15, Raw_Oil!$A:$A, "<"&EDATE(A15,1)), "") -> 88.578421 | F15: {=IFERROR(AVERAGEIFS(Raw_Inflation!$B:$B, Raw_Inflation!$A:$A, ">="&A15, Raw_Inflation!$A:$A, "<"&EDATE(A15,1)), "")} -> 2.3384211 | G15: {=IFERROR(VLOOKUP("Q"&INT((MONTH(A15)+2)/3)&"'"&TEXT(YEAR(A15)-2000,"00"), Raw_CB_demand!$A:$B, 2, 0), "")} -> 142.46376 | H15: =IFERROR((B15-B14)/B14, "") -> 0.012039221 | I15: =IFERROR((C15-C14)/C14*100, "") -> -0.79294291 | J15: =IF(A15<DATE(2020,3,1),"1_Pre-COVID",IF(A15<DATE(2022,1,1),"2_COVID-Recovery",IF(A15<DATE(2024,1,1),"3_Fed-Hike","4_Bull-Conflict"))) -> 1_Pre-COVID | K15: =IFERROR(_xlfn.STDEV.S(H4:H15), "") -> 0.026577884 | L15: =IFERROR(CORREL(B4:B15,C4:C15),"") -> -0.7316139 | M15: =IFERROR(CORREL(B4:B15,D4:D15),"") -> -0.6886519
A16: =EDATE(A15,1) -> 40603 | B16: {=IFERROR(INDEX(Raw_Gold!$B:$B, MATCH(1, (YEAR(Raw_Gold!$A:$A)=YEAR(A16))*(MONTH(Raw_Gold!$A:$A)=MONTH(A16)), 0)), "")} -> 1424.01 | C16: {=IFERROR(AVERAGEIFS(Raw_DXY!$B:$B, Raw_DXY!$A:$A, ">="&A16, Raw_DXY!$A:$A, "<"&EDATE(A16,1)), "")} -> 88.487226 | D16: =IFERROR(AVERAGEIFS(Raw_Real_Rate!$B:$B, Raw_Real_Rate!$A:$A, ">="&A16, Raw_Real_Rate!$A:$A, "<"&EDATE(A16,1)), "") -> 0.96391304 | E16: =IFERROR(AVERAGEIFS(Raw_Oil!$B:$B, Raw_Oil!$A:$A, ">="&A16, Raw_Oil!$A:$A, "<"&EDATE(A16,1)), "") -> 102.85652 | F16: {=IFERROR(AVERAGEIFS(Raw_Inflation!$B:$B, Raw_Inflation!$A:$A, ">="&A16, Raw_Inflation!$A:$A, "<"&EDATE(A16,1)), "")} -> 2.4504348 | G16: {=IFERROR(VLOOKUP("Q"&INT((MONTH(A16)+2)/3)&"'"&TEXT(YEAR(A16)-2000,"00"), Raw_CB_demand!$A:$B, 2, 0), "")} -> 142.46376 | H16: =IFERROR((B16-B15)/B15, "") -> 0.037356217 | I16: =IFERROR((C16-C15)/C15*100, "") -> -1.0173345 | J16: =IF(A16<DATE(2020,3,1),"1_Pre-COVID",IF(A16<DATE(2022,1,1),"2_COVID-Recovery",IF(A16<DATE(2024,1,1),"3_Fed-Hike","4_Bull-Conflict"))) -> 1_Pre-COVID | K16: =IFERROR(_xlfn.STDEV.S(H5:H16), "") -> 0.027053359 | L16: =IFERROR(CORREL(B5:B16,C5:C16),"") -> -0.83721704 | M16: =IFERROR(CORREL(B5:B16,D5:D16),"") -> -0.59095469
A17: =EDATE(A16,1) -> 40634 | B17: {=IFERROR(INDEX(Raw_Gold!$B:$B, MATCH(1, (YEAR(Raw_Gold!$A:$A)=YEAR(A17))*(MONTH(Raw_Gold!$A:$A)=MONTH(A17)), 0)), "")} -> 1473.81 | C17: {=IFERROR(AVERAGEIFS(Raw_DXY!$B:$B, Raw_DXY!$A:$A, ">="&A17, Raw_DXY!$A:$A, "<"&EDATE(A17,1)), "")} -> 86.921367 | D17: =IFERROR(AVERAGEIFS(Raw_Real_Rate!$B:$B, Raw_Real_Rate!$A:$A, ">="&A17, Raw_Real_Rate!$A:$A, "<"&EDATE(A17,1)), "") -> 0.8635 | E17: =IFERROR(AVERAGEIFS(Raw_Oil!$B:$B, Raw_Oil!$A:$A, ">="&A17, Raw_Oil!$A:$A, "<"&EDATE(A17,1)), "") -> 109.5325 | F17: {=IFERROR(AVERAGEIFS(Raw_Inflation!$B:$B, Raw_Inflation!$A:$A, ">="&A17, Raw_Inflation!$A:$A, "<"&EDATE(A17,1)), "")} -> 2.5915 | G17: {=IFERROR(VLOOKUP("Q"&INT((MONTH(A17)+2)/3)&"'"&TEXT(YEAR(A17)-2000,"00"), Raw_CB_demand!$A:$B, 2, 0), "")} -> 69.444805 | H17: =IFERROR((B17-B16)/B16, "") -> 0.034971665 | I17: =IFERROR((C17-C16)/C16*100, "") -> -1.7695881 | J17: =IF(A17<DATE(2020,3,1),"1_Pre-COVID",IF(A17<DATE(2022,1,1),"2_COVID-Recovery",IF(A17<DATE(2024,1,1),"3_Fed-Hike","4_Bull-Conflict"))) -> 1_Pre-COVID | K17: =IFERROR(_xlfn.STDEV.S(H6:H17), "") -> 0.027184771 | L17: =IFERROR(CORREL(B6:B17,C6:C17),"") -> -0.94490358 | M17: =IFERROR(CORREL(B6:B17,D6:D17),"") -> -0.48059715
A18: =EDATE(A17,1) -> 40664 | B18: {=IFERROR(INDEX(Raw_Gold!$B:$B, MATCH(1, (YEAR(Raw_Gold!$A:$A)=YEAR(A18))*(MONTH(Raw_Gold!$A:$A)=MONTH(A18)), 0)), "")} -> 1510.44 | C18: {=IFERROR(AVERAGEIFS(Raw_DXY!$B:$B, Raw_DXY!$A:$A, ">="&A18, Raw_DXY!$A:$A, "<"&EDATE(A18,1)), "")} -> 86.946405 | D18: =IFERROR(AVERAGEIFS(Raw_Real_Rate!$B:$B, Raw_Real_Rate!$A:$A, ">="&A18, Raw_Real_Rate!$A:$A, "<"&EDATE(A18,1)), "") -> 0.77857143 | E18: =IFERROR(AVERAGEIFS(Raw_Oil!$B:$B, Raw_Oil!$A:$A, ">="&A18, Raw_Oil!$A:$A, "<"&EDATE(A18,1)), "") -> 100.90048 | F18: {=IFERROR(AVERAGEIFS(Raw_Inflation!$B:$B, Raw_Inflation!$A:$A, ">="&A18, Raw_Inflation!$A:$A, "<"&EDATE(A18,1)), "")} -> 2.39 | G18: {=IFERROR(VLOOKUP("Q"&INT((MONTH(A18)+2)/3)&"'"&TEXT(YEAR(A18)-2000,"00"), Raw_CB_demand!$A:$B, 2, 0), "")} -> 69.444805 | H18: =IFERROR((B18-B17)/B17, "") -> 0.02485395 | I18: =IFERROR((C18-C17)/C17*100, "") -> 0.028805455 | J18: =IF(A18<DATE(2020,3,1),"1_Pre-COVID",IF(A18<DATE(2022,1,1),"2_COVID-Recovery",IF(A18<DATE(2024,1,1),"3_Fed-Hike","4_Bull-Conflict"))) -> 1_Pre-COVID | K18: =IFERROR(_xlfn.STDEV.S(H7:H18), "") -> 0.025767014 | L18: =IFERROR(CORREL(B7:B18,C7:C18),"") -> -0.94542827 | M18: =IFERROR(CORREL(B7:B18,D7:D18),"") -> -0.45260694
A19: =EDATE(A18,1) -> 40695 | B19: {=IFERROR(INDEX(Raw_Gold!$B:$B, MATCH(1, (YEAR(Raw_Gold!$A:$A)=YEAR(A19))*(MONTH(Raw_Gold!$A:$A)=MONTH(A19)), 0)), "")} -> 1528.66 | C19: {=IFERROR(AVERAGEIFS(Raw_DXY!$B:$B, Raw_DXY!$A:$A, ">="&A19, Raw_DXY!$A:$A, "<"&EDATE(A19,1)), "")} -> 86.941255 | D19: =IFERROR(AVERAGEIFS(Raw_Real_Rate!$B:$B, Raw_Real_Rate!$A:$A, ">="&A19, Raw_Real_Rate!$A:$A, "<"&EDATE(A19,1)), "") -> 0.75545455 | E19: =IFERROR(AVERAGEIFS(Raw_Oil!$B:$B, Raw_Oil!$A:$A, ">="&A19, Raw_Oil!$A:$A, "<"&EDATE(A19,1)), "") -> 96.264091 | F19: {=IFERROR(AVERAGEIFS(Raw_Inflation!$B:$B, Raw_Inflation!$A:$A, ">="&A19, Raw_Inflation!$A:$A, "<"&EDATE(A19,1)), "")} -> 2.2468182 | G19: {=IFERROR(VLOOKUP("Q"&INT((MONTH(A19)+2)/3)&"'"&TEXT(YEAR(A19)-2000,"00"), Raw_CB_demand!$A:$B, 2, 0), "")} -> 69.444805 | H19: =IFERROR((B19-B18)/B18, "") -> 0.01206271 | I19: =IFERROR((C19-C18)/C18*100, "") -> -0.0059234381 | J19: =IF(A19<DATE(2020,3,1),"1_Pre-COVID",IF(A19<DATE(2022,1,1),"2_COVID-Recovery",IF(A19<DATE(2024,1,1),"3_Fed-Hike","4_Bull-Conflict"))) -> 1_Pre-COVID | K19: =IFERROR(_xlfn.STDEV.S(H8:H19), "") -> 0.025819868 | L19: =IFERROR(CORREL(B8:B19,C8:C19),"") -> -0.96861112 | M19: =IFERROR(CORREL(B8:B19,D8:D19),"") -> -0.42409479
A20: =EDATE(A19,1) -> 40725 | B20: {=IFERROR(INDEX(Raw_Gold!$B:$B, MATCH(1, (YEAR(Raw_Gold!$A:$A)=YEAR(A20))*(MONTH(Raw_Gold!$A:$A)=MONTH(A20)), 0)), "")} -> 1572.81 | C20: {=IFERROR(AVERAGEIFS(Raw_DXY!$B:$B, Raw_DXY!$A:$A, ">="&A20, Raw_DXY!$A:$A, "<"&EDATE(A20,1)), "")} -> 86.317805 | D20: =IFERROR(AVERAGEIFS(Raw_Real_Rate!$B:$B, Raw_Real_Rate!$A:$A, ">="&A20, Raw_Real_Rate!$A:$A, "<"&EDATE(A20,1)), "") -> 0.6235 | E20: =IFERROR(AVERAGEIFS(Raw_Oil!$B:$B, Raw_Oil!$A:$A, ">="&A20, Raw_Oil!$A:$A, "<"&EDATE(A20,1)), "") -> 97.3035 | F20: {=IFERROR(AVERAGEIFS(Raw_Inflation!$B:$B, Raw_Inflation!$A:$A, ">="&A20, Raw_Inflation!$A:$A, "<"&EDATE(A20,1)), "")} -> 2.3795 | G20: {=IFERROR(VLOOKUP("Q"&INT((MONTH(A20)+2)/3)&"'"&TEXT(YEAR(A20)-2000,"00"), Raw_CB_demand!$A:$B, 2, 0), "")} -> 148.80804 | H20: =IFERROR((B20-B19)/B19, "") -> 0.028881504 | I20: =IFERROR((C20-C19)/C19*100, "") -> -0.71709288 | J20: =IF(A20<DATE(2020,3,1),"1_Pre-COVID",IF(A20<DATE(2022,1,1),"2_COVID-Recovery",IF(A20<DATE(2024,1,1),"3_Fed-Hike","4_Bull-Conflict"))) -> 1_Pre-COVID | K20: =IFERROR(_xlfn.STDEV.S(H9:H20), "") -> 0.0203413 | L20: =IFERROR(CORREL(B9:B20,C9:C20),"") -> -0.95976569 | M20: =IFERROR(CORREL(B9:B20,D9:D20),"") -> -0.38278701
A21: =EDATE(A20,1) -> 40756 | B21: {=IFERROR(INDEX(Raw_Gold!$B:$B, MATCH(1, (YEAR(Raw_Gold!$A:$A)=YEAR(A21))*(MONTH(Raw_Gold!$A:$A)=MONTH(A21)), 0)), "")} -> 1755.81 | C21: {=IFERROR(AVERAGEIFS(Raw_DXY!$B:$B, Raw_DXY!$A:$A, ">="&A21, Raw_DXY!$A:$A, "<"&EDATE(A21,1)), "")} -> 86.898243 | D21: =IFERROR(AVERAGEIFS(Raw_Real_Rate!$B:$B, Raw_Real_Rate!$A:$A, ">="&A21, Raw_Real_Rate!$A:$A, "<"&EDATE(A21,1)), "") -> 0.13521739 | E21: =IFERROR(AVERAGEIFS(Raw_Oil!$B:$B, Raw_Oil!$A:$A, ">="&A21, Raw_Oil!$A:$A, "<"&EDATE(A21,1)), "") -> 86.333043 | F21: {=IFERROR(AVERAGEIFS(Raw_Inflation!$B:$B, Raw_Inflation!$A:$A, ">="&A21, Raw_Inflation!$A:$A, "<"&EDATE(A21,1)), "")} -> 2.1678261 | G21: {=IFERROR(VLOOKUP("Q"&INT((MONTH(A21)+2)/3)&"'"&TEXT(YEAR(A21)-2000,"00"), Raw_CB_demand!$A:$B, 2, 0), "")} -> 148.80804 | H21: =IFERROR((B21-B20)/B20, "") -> 0.11635226 | I21: =IFERROR((C21-C20)/C20*100, "") -> 0.67244351 | J21: =IF(A21<DATE(2020,3,1),"1_Pre-COVID",IF(A21<DATE(2022,1,1),"2_COVID-Recovery",IF(A21<DATE(2024,1,1),"3_Fed-Hike","4_Bull-Conflict"))) -> 1_Pre-COVID | K21: =IFERROR(_xlfn.STDEV.S(H10:H21), "") -> 0.033532454 | L21: =IFERROR(CORREL(B10:B21,C10:C21),"") -> -0.8234704 | M21: =IFERROR(CORREL(B10:B21,D10:D21),"") -> -0.67991505
A22: =EDATE(A21,1) -> 40787 | B22: {=IFERROR(INDEX(Raw_Gold!$B:$B, MATCH(1, (YEAR(Raw_Gold!$A:$A)=YEAR(A22))*(MONTH(Raw_Gold!$A:$A)=MONTH(A22)), 0)), "")} -> 1771.85 | C22: {=IFERROR(AVERAGEIFS(Raw_DXY!$B:$B, Raw_DXY!$A:$A, ">="&A22, Raw_DXY!$A:$A, "<"&EDATE(A22,1)), "")} -> 89.725267 | D22: =IFERROR(AVERAGEIFS(Raw_Real_Rate!$B:$B, Raw_Real_Rate!$A:$A, ">="&A22, Raw_Real_Rate!$A:$A, "<"&EDATE(A22,1)), "") -> 0.077619048 | E22: =IFERROR(AVERAGEIFS(Raw_Oil!$B:$B, Raw_Oil!$A:$A, ">="&A22, Raw_Oil!$A:$A, "<"&EDATE(A22,1)), "") -> 85.515238 | F22: {=IFERROR(AVERAGEIFS(Raw_Inflation!$B:$B, Raw_Inflation!$A:$A, ">="&A22, Raw_Inflation!$A:$A, "<"&EDATE(A22,1)), "")} -> 1.897619 | G22: {=IFERROR(VLOOKUP("Q"&INT((MONTH(A22)+2)/3)&"'"&TEXT(YEAR(A22)-2000,"00"), Raw_CB_demand!$A:$B, 2, 0), "")} -> 148.80804 | H22: =IFERROR((B22-B21)/B21, "") -> 0.0091353848 | I22: =IFERROR((C22-C21)/C21*100, "") -> 3.253257 | J22: =IF(A22<DATE(2020,3,1),"1_Pre-COVID",IF(A22<DATE(2022,1,1),"2_COVID-Recovery",IF(A22<DATE(2024,1,1),"3_Fed-Hike","4_Bull-Conflict"))) -> 1_Pre-COVID | K22: =IFERROR(_xlfn.STDEV.S(H11:H22), "") -> 0.033808741 | L22: =IFERROR(CORREL(B11:B22,C11:C22),"") -> -0.49539123 | M22: =IFERROR(CORREL(B11:B22,D11:D22),"") -> -0.80354689
A23: =EDATE(A22,1) -> 40817 | B23: {=IFERROR(INDEX(Raw_Gold!$B:$B, MATCH(1, (YEAR(Raw_Gold!$A:$A)=YEAR(A23))*(MONTH(Raw_Gold!$A:$A)=MONTH(A23)), 0)), "")} -> 1665.21 | C23: {=IFERROR(AVERAGEIFS(Raw_DXY!$B:$B, Raw_DXY!$A:$A, ">="&A23, Raw_DXY!$A:$A, "<"&EDATE(A23,1)), "")} -> 90.609845 | D23: =IFERROR(AVERAGEIFS(Raw_Real_Rate!$B:$B, Raw_Real_Rate!$A:$A, ">="&A23, Raw_Real_Rate!$A:$A, "<"&EDATE(A23,1)), "") -> 0.186 | E23: =IFERROR(AVERAGEIFS(Raw_Oil!$B:$B, Raw_Oil!$A:$A, ">="&A23, Raw_Oil!$A:$A, "<"&EDATE(A23,1)), "") -> 86.322381 | F23: {=IFERROR(AVERAGEIFS(Raw_Inflation!$B:$B, Raw_Inflation!$A:$A, ">="&A23, Raw_Inflation!$A:$A, "<"&EDATE(A23,1)), "")} -> 1.966 | G23: {=IFERROR(VLOOKUP("Q"&INT((MONTH(A23)+2)/3)&"'"&TEXT(YEAR(A23)-2000,"00"), Raw_CB_demand!$A:$B, 2, 0), "")} -> 120.06989 | H23: =IFERROR((B23-B22)/B22, "") -> -0.060185682 | I23: =IFERROR((C23-C22)/C22*100, "") -> 0.98587429 | J23: =IF(A23<DATE(2020,3,1),"1_Pre-COVID",IF(A23<DATE(2022,1,1),"2_COVID-Recovery",IF(A23<DATE(2024,1,1),"3_Fed-Hike","4_Bull-Conflict"))) -> 1_Pre-COVID | K23: =IFERROR(_xlfn.STDEV.S(H12:H23), "") -> 0.041100083 | L23: =IFERROR(CORREL(B12:B23,C12:C23),"") -> -0.28869222 | M23: =IFERROR(CORREL(B12:B23,D12:D23),"") -> -0.92520547
A24: =EDATE(A23,1) -> 40848 | B24: {=IFERROR(INDEX(Raw_Gold!$B:$B, MATCH(1, (YEAR(Raw_Gold!$A:$A)=YEAR(A24))*(MONTH(Raw_Gold!$A:$A)=MONTH(A24)), 0)), "")} -> 1738.98 | C24: {=IFERROR(AVERAGEIFS(Raw_DXY!$B:$B, Raw_DXY!$A:$A, ">="&A24, Raw_DXY!$A:$A, "<"&EDATE(A24,1)), "")} -> 91.26488 | D24: =IFERROR(AVERAGEIFS(Raw_Real_Rate!$B:$B, Raw_Real_Rate!$A:$A, ">="&A24, Raw_Real_Rate!$A:$A, "<"&EDATE(A24,1)), "") -> 0.0015 | E24: =IFERROR(AVERAGEIFS(Raw_Oil!$B:$B, Raw_Oil!$A:$A, ">="&A24, Raw_Oil!$A:$A, "<"&EDATE(A24,1)), "") -> 97.160476 | F24: {=IFERROR(AVERAGEIFS(Raw_Inflation!$B:$B, Raw_Inflation!$A:$A, ">="&A24, Raw_Inflation!$A:$A, "<"&EDATE(A24,1)), "")} -> 2.012 | G24: {=IFERROR(VLOOKUP("Q"&INT((MONTH(A24)+2)/3)&"'"&TEXT(YEAR(A24)-2000,"00"), Raw_CB_demand!$A:$B, 2, 0), "")} -> 120.06989 | H24: =IFERROR((B24-B23)/B23, "") -> 0.044300719 | I24: =IFERROR((C24-C23)/C23*100, "") -> 0.72291813 | J24: =IF(A24<DATE(2020,3,1),"1_Pre-COVID",IF(A24<DATE(2022,1,1),"2_COVID-Recovery",IF(A24<DATE(2024,1,1),"3_Fed-Hike","4_Bull-Conflict"))) -> 1_Pre-COVID | K24: =IFERROR(_xlfn.STDEV.S(H13:H24), "") -> 0.041753726 | L24: =IFERROR(CORREL(B13:B24,C13:C24),"") -> -0.004810826 | M24: =IFERROR(CORREL(B13:B24,D13:D24),"") -> -0.98262512
A25: =EDATE(A24,1) -> 40878 | B25: {=IFERROR(INDEX(Raw_Gold!$B:$B, MATCH(1, (YEAR(Raw_Gold!$A:$A)=YEAR(A25))*(MONTH(Raw_Gold!$A:$A)=MONTH(A25)), 0)), "")} -> 1652.31 | C25: {=IFERROR(AVERAGEIFS(Raw_DXY!$B:$B, Raw_DXY!$A:$A, ">="&A25, Raw_DXY!$A:$A, "<"&EDATE(A25,1)), "")} -> 92.20559 | D25: =IFERROR(AVERAGEIFS(Raw_Real_Rate!$B:$B, Raw_Real_Rate!$A:$A, ">="&A25, Raw_Real_Rate!$A:$A, "<"&EDATE(A25,1)), "") -> -0.031428571 | E25: =IFERROR(AVERAGEIFS(Raw_Oil!$B:$B, Raw_Oil!$A:$A, ">="&A25, Raw_Oil!$A:$A, "<"&EDATE(A25,1)), "") -> 98.562857 | F25: {=IFERROR(AVERAGEIFS(Raw_Inflation!$B:$B, Raw_Inflation!$A:$A, ">="&A25, Raw_Inflation!$A:$A, "<"&EDATE(A25,1)), "")} -> 2.0095238 | G25: {=IFERROR(VLOOKUP("Q"&INT((MONTH(A25)+2)/3)&"'"&TEXT(YEAR(A25)-2000,"00"), Raw_CB_demand!$A:$B, 2, 0), "")} -> 120.06989 | H25: =IFERROR((B25-B24)/B24, "") -> -0.049839561 | I25: =IFERROR((C25-C24)/C24*100, "") -> 1.0307475 | J25: =IF(A25<DATE(2020,3,1),"1_Pre-COVID",IF(A25<DATE(2022,1,1),"2_COVID-Recovery",IF(A25<DATE(2024,1,1),"3_Fed-Hike","4_Bull-Conflict"))) -> 1_Pre-COVID | K25: =IFERROR(_xlfn.STDEV.S(H14:H25), "") -> 0.046505721 | L25: =IFERROR(CORREL(B14:B25,C14:C25),"") -> 0.21858262 | M25: =IFERROR(CORREL(B14:B25,D14:D25),"") -> -0.95489778
... A196: =EDATE(A195,1) -> 46082 | B196: {=IFERROR(INDEX(Raw_Gold!$B:$B, MATCH(1, (YEAR(Raw_Gold!$A:$A)=YEAR(A196))*(MONTH(Raw_Gold!$A:$A)=MONTH(A196)), 0)), "")} -> 4862.17 | C196: {=IFERROR(AVERAGEIFS(Raw_DXY!$B:$B, Raw_DXY!$A:$A, ">="&A196, Raw_DXY!$A:$A, "<"&EDATE(A196,1)), "")} -> 119.91985 | D196: =IFERROR(AVERAGEIFS(Raw_Real_Rate!$B:$B, Raw_Real_Rate!$A:$A, ">="&A196, Raw_Real_Rate!$A:$A, "<"&EDATE(A196,1)), "") -> 1.9090909 | E196: =IFERROR(AVERAGEIFS(Raw_Oil!$B:$B, Raw_Oil!$A:$A, ">="&A196, Raw_Oil!$A:$A, "<"&EDATE(A196,1)), "") -> 91.383636 | F196: {=IFERROR(AVERAGEIFS(Raw_Inflation!$B:$B, Raw_Inflation!$A:$A, ">="&A196, Raw_Inflation!$A:$A, "<"&EDATE(A196,1)), "")} -> 2.3368182 | G196: {=IFERROR(VLOOKUP("Q"&INT((MONTH(A196)+2)/3)&"'"&TEXT(YEAR(A196)-2000,"00"), Raw_CB_demand!$A:$B, 2, 0), "")} -> 243.66413 | H196: =IFERROR((B196-B195)/B195, "") -> -0.031349549 | I196: =IFERROR((C196-C195)/C195*100, "") -> 1.7079989 | J196: =IF(A196<DATE(2020,3,1),"1_Pre-COVID",IF(A196<DATE(2022,1,1),"2_COVID-Recovery",IF(A196<DATE(2024,1,1),"3_Fed-Hike","4_Bull-Conflict"))) -> 4_Bull-Conflict | K196: =IFERROR(_xlfn.STDEV.S(H185:H196), "") -> 0.0453122 | L196: =IFERROR(CORREL(B185:B196,C185:C196),"") -> -0.6936002 | M196: =IFERROR(CORREL(B185:B196,D185:D196),"") -> -0.51446787

Sheet Sheet11
A1: ERA | B1: VARIABLE | C1: CORRELATION
A2: Era 1: Pre-COVID | B2: Gold vs DXY | C2: -0.46
A3: Era 1: Pre-COVID | B3: Gold vs Real Rate | C3: -0.69
A4: Era 1: Pre-COVID | B4: Gold vs Oil | C4: 0.5
A5: Era 1: Pre-COVID | B5: Gold vs Inflation | C5: 0.42
A6: Era 2: COVID Recovery | B6: Gold vs DXY | C6: -0.46
A7: Era 2: COVID Recovery | B7: Gold vs Real Rate | C7: -0.78
A8: Era 2: COVID Recovery | B8: Gold vs Oil | C8: 0.16
A9: Era 2: COVID Recovery | B9: Gold vs Inflation | C9: 0.28
A10: Era 3: Fed Hike | B10: Gold vs DXY | C10: -0.58
A11: Era 3: Fed Hike | B11: Gold vs Real Rate | C11: 0.19
A12: Era 3: Fed Hike | B12: Gold vs Oil | C12: -0.3
A13: Era 3: Fed Hike | B13: Gold vs Inflation | C13: -0.14
... A17: Era 4: Bull-Conflict | B17: Gold vs Inflation | C17: 0.12

Sheet Analysis
A1: TEST 1 - CORRELATION MATRIX
B3: GOLD_USD | C3: DXY | D3: REAL_RATE | E3: OIL_WTI | F3: INFLATION_EXP
A4: GOLD_USD | B4: 1
A5: DXY | B5: 0.4328725 | C5: 1
A6: REAL_RATE | B6: 0.41687525 | C6: 0.33876806 | D6: 1
A7: OIL_WTI | B7: 0.041621138 | C7: -0.51015684 | D7: 0.07946251 | E7: 1
A8: INFLATION_EXP | B8: 0.36359203 | C8: -0.10114541 | D8: 0.19696812 | E8: 0.76173059 | F8: 1
A11: Note: Full period correlations mask significant strucutral changes across 4 Macro eras. See Test 2 for era-by-era breakdown.
A13: TEST 2 - CORRELATION BY ERA
A15: Era 1- Pre- Covid (Jan 2010- Feb 2020) | B15: GOLD_USD | C15: DXY | D15: REAL_RATE | E15: OIL_WTI | F15: INFLATION_EXP
A16: GOLD_USD | B16: 1
A17: DXY | B17: -0.45965455 | C17: 1
A18: REAL_RATE | B18: -0.69199794 | C18: 0.13443702 | D18: 1
A19: OIL_WTI | B19: 0.50470814 | C19: -0.87673984 | D19: -0.14919494 | E19: 1
A20: INFLATION_EXP | B20: 0.42087257 | C20: -0.71725973 | D20: -0.10236293 | E20: 0.82616639 | F20: 1
A24: Era 2- COVID Recovery (Mar 2020-Dec 2021) | B24: GOLD_USD | C24: DXY | D24: REAL_RATE | E24: OIL_WTI | F24: INFLATION_EXP
A25: GOLD_USD | B25: 1
A26: DXY | B26: -0.46445694 | C26: 1
A27: REAL_RATE | B27: -0.77900798 | C27: 0.68973112 | D27: 1
A28: OIL_WTI | B28: 0.15645175 | C28: -0.73949461 | D28: -0.62583483 | E28: 1
A29: INFLATION_EXP | B29: 0.28216306 | C29: -0.83791802 | D29: -0.7089756 | E29: 0.95675577 | F29: 1
A32: Era 3- Fed Hike (Jan 2022-Dec 2023) | B32: GOLD_USD | C32: DXY | D32: REAL_RATE | E32: OIL_WTI | F32: INFLATION_EXP
A33: GOLD_USD | B33: 1
A34: DXY | B34: -0.58434177 | C34: 1
A35: REAL_RATE | B35: 0.19479474 | C35: 0.58700087 | D35: 1
A36: OIL_WTI | B36: -0.30363347 | C36: -0.1002934 | D36: -0.6128103 | E36: 1
A37: INFLATION_EXP | B37: -0.13958356 | C37: -0.29227307 | D37: -0.70565944 | E37: 0.85496996 | F37: 1
A40: Era 4- Bull Conflict (Jan 2024-Mar 2026) | B40: GOLD_USD | C40: DXY | D40: REAL_RATE | E40: OIL_WTI | F40: INFLATION_EXP
A41: GOLD_USD | B41: 1
A42: DXY | B42: -0.46720765 | C42: 1
A43: REAL_RATE | B43: -0.23753267 | C43: 0.49693041 | D43: 1
A44: OIL_WTI | B44: -0.48956172 | C44: 0.14819267 | D44: 0.254758 | E44: 1
A45: INFLATION_EXP | B45: 0.12128427 | C45: 0.17863912 | D45: 0.53844383 | E45: 0.072228064 | F45: 1
A48: TEST 3 - MULTIPLE REGRESSION
A50: SUMMARY OUTPUT
A52: Regression Statistics
A53: Multiple R | B53: 0.63430137
A54: R Square | B54: 0.40233823
A55: Adjusted R Square | B55: 0.38975587
A56: Standard Error | B56: 547.9083
...

Sheet Charts
A1: DATE | B1: GOLD_USD | C1: DXY | D1: ERA
A2: ='Master Data'!A2 -> 40179 | B2: ='Master Data'!B2 -> 1117.96 | C2: ='Master Data'!C2 -> 92.4403 | D2: ='Master Data'!J2 -> 1_Pre-COVID
A3: ='Master Data'!A3 -> 40210 | B3: ='Master Data'!B3 -> 1095.41 | C3: ='Master Data'!C3 -> 93.88668 | D3: ='Master Data'!J3 -> 1_Pre-COVID
A4: ='Master Data'!A4 -> 40238 | B4: ='Master Data'!B4 -> 1113.34 | C4: ='Master Data'!C4 -> 93.149878 | D4: ='Master Data'!J4 -> 1_Pre-COVID
A5: ='Master Data'!A5 -> 40269 | B5: ='Master Data'!B5 -> 1148.69 | C5: ='Master Data'!C5 -> 92.639086 | D5: ='Master Data'!J5 -> 1_Pre-COVID
A6: ='Master Data'!A6 -> 40299 | B6: ='Master Data'!B6 -> 1205.43 | C6: ='Master Data'!C6 -> 95.53064 | D6: ='Master Data'!J6 -> 1_Pre-COVID
A7: ='Master Data'!A7 -> 40330 | B7: ='Master Data'!B7 -> 1232.92 | C7: ='Master Data'!C7 -> 96.060627 | D7: ='Master Data'!J7 -> 1_Pre-COVID
A8: ='Master Data'!A8 -> 40360 | B8: ='Master Data'!B8 -> 1192.97 | C8: ='Master Data'!C8 -> 94.45469 | D8: ='Master Data'!J8 -> 1_Pre-COVID
A9: ='Master Data'!A9 -> 40391 | B9: ='Master Data'!B9 -> 1215.81 | C9: ='Master Data'!C9 -> 93.682232 | D9: ='Master Data'!J9 -> 1_Pre-COVID
A10: ='Master Data'!A10 -> 40422 | B10: ='Master Data'!B10 -> 1270.98 | C10: ='Master Data'!C10 -> 92.762595 | D10: ='Master Data'!J10 -> 1_Pre-COVID
A11: ='Master Data'!A11 -> 40452 | B11: ='Master Data'!B11 -> 1342.02 | C11: ='Master Data'!C11 -> 90.22912 | D11: ='Master Data'!J11 -> 1_Pre-COVID
A12: ='Master Data'!A12 -> 40483 | B12: ='Master Data'!B12 -> 1369.89 | C12: ='Master Data'!C12 -> 90.509535 | D12: ='Master Data'!J12 -> 1_Pre-COVID
A13: ='Master Data'!A13 -> 40513 | B13: ='Master Data'!B13 -> 1390.55 | C13: ='Master Data'!C13 -> 91.183471 | D13: ='Master Data'!J13 -> 1_Pre-COVID
... A196: ='Master Data'!A196 -> 46082 | B196: ='Master Data'!B196 -> 4862.17 | C196: ='Master Data'!C196 -> 119.91985 | D196: ='Master Data'!J196 -> 4_Bull-Conflict
